2025-02-08 10:55:14 - INFO - Start polling
2025-02-08 10:55:14 - INFO - Run polling for bot @odfopjdfiohniodfhopjdfh_bot id=7915533202 - 'ijdsgijsiodgjsiodgjiosg'
2025-02-08 10:55:23 - INFO - Update id=652331061 is handled. Duration 296 ms by bot id=7915533202
2025-02-08 10:55:25 - INFO - Connecting to 149.154.175.53:443/TcpFull...
2025-02-08 10:55:25 - INFO - Connection to 149.154.175.53:443/TcpFull complete!
2025-02-08 10:55:30 - INFO - Starting direct file download in chunks of 131072 at 0, stride 131072
2025-02-08 10:55:30 - INFO - File lives in another DC
2025-02-08 10:55:30 - INFO - Connecting to 149.154.167.41:443/TcpFull...
2025-02-08 10:55:32 - INFO - Connection to 149.154.167.41:443/TcpFull complete!
2025-02-08 10:55:32 - INFO - Exporting auth for new borrowed sender in DcOption(id=2, ip_address='149.154.167.41', port=443, ipv6=False, media_only=False, tcpo_only=False, cdn=False, static=False, this_port_only=False, secret=None)
2025-02-08 10:55:38 - INFO - Disconnecting from 149.154.175.53:443/TcpFull...
2025-02-08 10:55:38 - INFO - Disconnection from 149.154.175.53:443/TcpFull complete!
2025-02-08 10:55:38 - INFO - Disconnecting from 149.154.167.41:443/TcpFull...
2025-02-08 10:55:38 - INFO - Disconnection from 149.154.167.41:443/TcpFull complete!
2025-02-08 10:55:47 - INFO - Update id=652331062 is not handled. Duration 22344 ms by bot id=7915533202
2025-02-08 10:55:47 - ERROR - Cause exception while process update id=652331062 by bot id=7915533202
JSONDecodeError: Expecting value: line 1 column 1 (char 0)
Traceback (most recent call last):
  File "c:\Users\RUSTYCHKA\AppData\Local\Programs\Python\Python312\Lib\site-packages\requests\models.py", line 971, in json
    return complexjson.loads(self.text, **kwargs)
           ^^^^^^^^^^^^^^^^^^^^^^^^^^^^^^^^^^^^^^
  File "c:\Users\RUSTYCHKA\AppData\Local\Programs\Python\Python312\Lib\json\__init__.py", line 346, in loads
    return _default_decoder.decode(s)
           ^^^^^^^^^^^^^^^^^^^^^^^^^^
  File "c:\Users\RUSTYCHKA\AppData\Local\Programs\Python\Python312\Lib\json\decoder.py", line 337, in decode
    obj, end = self.raw_decode(s, idx=_w(s, 0).end())
               ^^^^^^^^^^^^^^^^^^^^^^^^^^^^^^^^^^^^^^
  File "c:\Users\RUSTYCHKA\AppData\Local\Programs\Python\Python312\Lib\json\decoder.py", line 355, in raw_decode
    raise JSONDecodeError("Expecting value", s, err.value) from None
json.decoder.JSONDecodeError: Expecting value: line 1 column 1 (char 0)

During handling of the above exception, another exception occurred:

Traceback (most recent call last):
  File "c:\Users\RUSTYCHKA\AppData\Local\Programs\Python\Python312\Lib\site-packages\aiogram\dispatcher\dispatcher.py", line 309, in _process_update
    response = await self.feed_update(bot, update, **kwargs)
               ^^^^^^^^^^^^^^^^^^^^^^^^^^^^^^^^^^^^^^^^^^^^^
  File "c:\Users\RUSTYCHKA\AppData\Local\Programs\Python\Python312\Lib\site-packages\aiogram\dispatcher\dispatcher.py", line 158, in feed_update
    response = await self.update.wrap_outer_middleware(
               ^^^^^^^^^^^^^^^^^^^^^^^^^^^^^^^^^^^^^^^^
  File "c:\Users\RUSTYCHKA\AppData\Local\Programs\Python\Python312\Lib\site-packages\aiogram\dispatcher\middlewares\error.py", line 25, in __call__
    return await handler(event, data)
           ^^^^^^^^^^^^^^^^^^^^^^^^^^
  File "c:\Users\RUSTYCHKA\AppData\Local\Programs\Python\Python312\Lib\site-packages\aiogram\dispatcher\middlewares\user_context.py", line 27, in __call__
    return await handler(event, data)
           ^^^^^^^^^^^^^^^^^^^^^^^^^^
  File "c:\Users\RUSTYCHKA\AppData\Local\Programs\Python\Python312\Lib\site-packages\aiogram\fsm\middleware.py", line 41, in __call__
    return await handler(event, data)
           ^^^^^^^^^^^^^^^^^^^^^^^^^^
  File "c:\Users\RUSTYCHKA\AppData\Local\Programs\Python\Python312\Lib\site-packages\aiogram\dispatcher\event\telegram.py", line 121, in trigger
    return await wrapped_inner(event, kwargs)
           ^^^^^^^^^^^^^^^^^^^^^^^^^^^^^^^^^^
  File "c:\Users\RUSTYCHKA\AppData\Local\Programs\Python\Python312\Lib\site-packages\aiogram\dispatcher\event\handler.py", line 43, in call
    return await wrapped()
           ^^^^^^^^^^^^^^^
  File "c:\Users\RUSTYCHKA\AppData\Local\Programs\Python\Python312\Lib\site-packages\aiogram\dispatcher\dispatcher.py", line 276, in _listen_update
    return await self.propagate_event(update_type=update_type, event=event, **kwargs)
           ^^^^^^^^^^^^^^^^^^^^^^^^^^^^^^^^^^^^^^^^^^^^^^^^^^^^^^^^^^^^^^^^^^^^^^^^^^
  File "c:\Users\RUSTYCHKA\AppData\Local\Programs\Python\Python312\Lib\site-packages\aiogram\dispatcher\router.py", line 128, in propagate_event
    return await observer.wrap_outer_middleware(_wrapped, event=event, data=kwargs)
           ^^^^^^^^^^^^^^^^^^^^^^^^^^^^^^^^^^^^^^^^^^^^^^^^^^^^^^^^^^^^^^^^^^^^^^^^
  File "c:\Users\RUSTYCHKA\AppData\Local\Programs\Python\Python312\Lib\site-packages\aiogram\dispatcher\router.py", line 123, in _wrapped
    return await self._propagate_event(
           ^^^^^^^^^^^^^^^^^^^^^^^^^^^^
  File "c:\Users\RUSTYCHKA\AppData\Local\Programs\Python\Python312\Lib\site-packages\aiogram\dispatcher\router.py", line 156, in _propagate_event
    response = await router.propagate_event(update_type=update_type, event=event, **kwargs)
               ^^^^^^^^^^^^^^^^^^^^^^^^^^^^^^^^^^^^^^^^^^^^^^^^^^^^^^^^^^^^^^^^^^^^^^^^^^^^
  File "c:\Users\RUSTYCHKA\AppData\Local\Programs\Python\Python312\Lib\site-packages\aiogram\dispatcher\router.py", line 128, in propagate_event
    return await observer.wrap_outer_middleware(_wrapped, event=event, data=kwargs)
           ^^^^^^^^^^^^^^^^^^^^^^^^^^^^^^^^^^^^^^^^^^^^^^^^^^^^^^^^^^^^^^^^^^^^^^^^
  File "c:\Users\RUSTYCHKA\AppData\Local\Programs\Python\Python312\Lib\site-packages\aiogram\dispatcher\router.py", line 123, in _wrapped
    return await self._propagate_event(
           ^^^^^^^^^^^^^^^^^^^^^^^^^^^^
  File "c:\Users\RUSTYCHKA\AppData\Local\Programs\Python\Python312\Lib\site-packages\aiogram\dispatcher\router.py", line 148, in _propagate_event
    response = await observer.trigger(event, **kwargs)
               ^^^^^^^^^^^^^^^^^^^^^^^^^^^^^^^^^^^^^^^
  File "c:\Users\RUSTYCHKA\AppData\Local\Programs\Python\Python312\Lib\site-packages\aiogram\dispatcher\event\telegram.py", line 121, in trigger
    return await wrapped_inner(event, kwargs)
           ^^^^^^^^^^^^^^^^^^^^^^^^^^^^^^^^^^
  File "c:\Users\RUSTYCHKA\AppData\Local\Programs\Python\Python312\Lib\site-packages\aiogram\dispatcher\event\handler.py", line 43, in call
    return await wrapped()
           ^^^^^^^^^^^^^^^
  File "C:\Users\RUSTYCHKA\Desktop\new_vk_project\handlers\start.py", line 249, in start_callback
    media = upload.photo(
            ^^^^^^^^^^^^^
  File "c:\Users\RUSTYCHKA\AppData\Local\Programs\Python\Python312\Lib\site-packages\vk_api\upload.py", line 72, in photo
    response = self.http.post(url, files=photo_files).json()
               ^^^^^^^^^^^^^^^^^^^^^^^^^^^^^^^^^^^^^^^^^^^^^
  File "c:\Users\RUSTYCHKA\AppData\Local\Programs\Python\Python312\Lib\site-packages\requests\models.py", line 975, in json
    raise RequestsJSONDecodeError(e.msg, e.doc, e.pos)
requests.exceptions.JSONDecodeError: Expecting value: line 1 column 1 (char 0)
