2025-02-09 16:46:07 - INFO - Start polling
2025-02-09 16:46:08 - INFO - Run polling for bot @odfopjdfiohniodfhopjdfh_bot id=7915533202 - 'ijdsgijsiodgjsiodgjiosg'
2025-02-09 17:16:12 - INFO - Update id=652331121 is handled. Duration 250 ms by bot id=7915533202
2025-02-09 17:16:14 - INFO - Connecting to 149.154.175.53:443/TcpFull...
2025-02-09 17:16:14 - INFO - Connection to 149.154.175.53:443/TcpFull complete!
2025-02-09 17:16:16 - INFO - Starting direct file download in chunks of 131072 at 0, stride 131072
2025-02-09 17:16:16 - INFO - File lives in another DC
2025-02-09 17:16:16 - INFO - Connecting to 149.154.167.41:443/TcpFull...
2025-02-09 17:16:19 - INFO - Connection to 149.154.167.41:443/TcpFull complete!
2025-02-09 17:16:19 - INFO - Exporting auth for new borrowed sender in DcOption(id=2, ip_address='149.154.167.41', port=443, ipv6=False, media_only=False, tcpo_only=False, cdn=False, static=False, this_port_only=False, secret=None)
2025-02-09 17:16:23 - INFO - Disconnecting from 149.154.175.53:443/TcpFull...
2025-02-09 17:16:23 - INFO - Disconnection from 149.154.175.53:443/TcpFull complete!
2025-02-09 17:16:23 - INFO - Disconnecting from 149.154.167.41:443/TcpFull...
2025-02-09 17:16:23 - INFO - Disconnection from 149.154.167.41:443/TcpFull complete!
2025-02-09 17:16:24 - INFO - Update id=652331122 is not handled. Duration 10031 ms by bot id=7915533202
2025-02-09 17:16:24 - ERROR - Cause exception while process update id=652331122 by bot id=7915533202
InvalidURL: Failed to parse: ['media\\image.png']
Traceback (most recent call last):
  File "c:\Users\RUSTYCHKA\AppData\Local\Programs\Python\Python312\Lib\site-packages\urllib3\util\url.py", line 423, in parse_url
    host, port = _HOST_PORT_RE.match(host_port).groups()  # type: ignore[union-attr]
                 ^^^^^^^^^^^^^^^^^^^^^^^^^^^^^^^^^^^^^
AttributeError: 'NoneType' object has no attribute 'groups'

The above exception was the direct cause of the following exception:

Traceback (most recent call last):
  File "c:\Users\RUSTYCHKA\AppData\Local\Programs\Python\Python312\Lib\site-packages\requests\models.py", line 433, in prepare_url
    scheme, auth, host, port, path, query, fragment = parse_url(url)
                                                      ^^^^^^^^^^^^^^
  File "c:\Users\RUSTYCHKA\AppData\Local\Programs\Python\Python312\Lib\site-packages\urllib3\util\url.py", line 449, in parse_url
    raise LocationParseError(source_url) from e
urllib3.exceptions.LocationParseError: Failed to parse: ['media\\image.png']

During handling of the above exception, another exception occurred:

Traceback (most recent call last):
  File "c:\Users\RUSTYCHKA\AppData\Local\Programs\Python\Python312\Lib\site-packages\aiogram\dispatcher\dispatcher.py", line 309, in _process_update
    response = await self.feed_update(bot, update, **kwargs)
               ^^^^^^^^^^^^^^^^^^^^^^^^^^^^^^^^^^^^^^^^^^^^^
  File "c:\Users\RUSTYCHKA\AppData\Local\Programs\Python\Python312\Lib\site-packages\aiogram\dispatcher\dispatcher.py", line 158, in feed_update
    response = await self.update.wrap_outer_middleware(
               ^^^^^^^^^^^^^^^^^^^^^^^^^^^^^^^^^^^^^^^^
  File "c:\Users\RUSTYCHKA\AppData\Local\Programs\Python\Python312\Lib\site-packages\aiogram\dispatcher\middlewares\error.py", line 25, in __call__
    return await handler(event, data)
           ^^^^^^^^^^^^^^^^^^^^^^^^^^
  File "c:\Users\RUSTYCHKA\AppData\Local\Programs\Python\Python312\Lib\site-packages\aiogram\dispatcher\middlewares\user_context.py", line 27, in __call__
    return await handler(event, data)
           ^^^^^^^^^^^^^^^^^^^^^^^^^^
  File "c:\Users\RUSTYCHKA\AppData\Local\Programs\Python\Python312\Lib\site-packages\aiogram\fsm\middleware.py", line 41, in __call__
    return await handler(event, data)
           ^^^^^^^^^^^^^^^^^^^^^^^^^^
  File "c:\Users\RUSTYCHKA\AppData\Local\Programs\Python\Python312\Lib\site-packages\aiogram\dispatcher\event\telegram.py", line 121, in trigger
    return await wrapped_inner(event, kwargs)
           ^^^^^^^^^^^^^^^^^^^^^^^^^^^^^^^^^^
  File "c:\Users\RUSTYCHKA\AppData\Local\Programs\Python\Python312\Lib\site-packages\aiogram\dispatcher\event\handler.py", line 43, in call
    return await wrapped()
           ^^^^^^^^^^^^^^^
  File "c:\Users\RUSTYCHKA\AppData\Local\Programs\Python\Python312\Lib\site-packages\aiogram\dispatcher\dispatcher.py", line 276, in _listen_update
    return await self.propagate_event(update_type=update_type, event=event, **kwargs)
           ^^^^^^^^^^^^^^^^^^^^^^^^^^^^^^^^^^^^^^^^^^^^^^^^^^^^^^^^^^^^^^^^^^^^^^^^^^
  File "c:\Users\RUSTYCHKA\AppData\Local\Programs\Python\Python312\Lib\site-packages\aiogram\dispatcher\router.py", line 128, in propagate_event
    return await observer.wrap_outer_middleware(_wrapped, event=event, data=kwargs)
           ^^^^^^^^^^^^^^^^^^^^^^^^^^^^^^^^^^^^^^^^^^^^^^^^^^^^^^^^^^^^^^^^^^^^^^^^
  File "c:\Users\RUSTYCHKA\AppData\Local\Programs\Python\Python312\Lib\site-packages\aiogram\dispatcher\router.py", line 123, in _wrapped
    return await self._propagate_event(
           ^^^^^^^^^^^^^^^^^^^^^^^^^^^^
  File "c:\Users\RUSTYCHKA\AppData\Local\Programs\Python\Python312\Lib\site-packages\aiogram\dispatcher\router.py", line 156, in _propagate_event
    response = await router.propagate_event(update_type=update_type, event=event, **kwargs)
               ^^^^^^^^^^^^^^^^^^^^^^^^^^^^^^^^^^^^^^^^^^^^^^^^^^^^^^^^^^^^^^^^^^^^^^^^^^^^
  File "c:\Users\RUSTYCHKA\AppData\Local\Programs\Python\Python312\Lib\site-packages\aiogram\dispatcher\router.py", line 128, in propagate_event
    return await observer.wrap_outer_middleware(_wrapped, event=event, data=kwargs)
           ^^^^^^^^^^^^^^^^^^^^^^^^^^^^^^^^^^^^^^^^^^^^^^^^^^^^^^^^^^^^^^^^^^^^^^^^
  File "c:\Users\RUSTYCHKA\AppData\Local\Programs\Python\Python312\Lib\site-packages\aiogram\dispatcher\router.py", line 123, in _wrapped
    return await self._propagate_event(
           ^^^^^^^^^^^^^^^^^^^^^^^^^^^^
  File "c:\Users\RUSTYCHKA\AppData\Local\Programs\Python\Python312\Lib\site-packages\aiogram\dispatcher\router.py", line 148, in _propagate_event
    response = await observer.trigger(event, **kwargs)
               ^^^^^^^^^^^^^^^^^^^^^^^^^^^^^^^^^^^^^^^
  File "c:\Users\RUSTYCHKA\AppData\Local\Programs\Python\Python312\Lib\site-packages\aiogram\dispatcher\event\telegram.py", line 121, in trigger
    return await wrapped_inner(event, kwargs)
           ^^^^^^^^^^^^^^^^^^^^^^^^^^^^^^^^^^
  File "c:\Users\RUSTYCHKA\AppData\Local\Programs\Python\Python312\Lib\site-packages\aiogram\dispatcher\event\handler.py", line 43, in call
    return await wrapped()
           ^^^^^^^^^^^^^^^
  File "C:\Users\RUSTYCHKA\Desktop\new_vk_project\handlers\start.py", line 235, in start_callback
    response = requests.get(post["media"])
               ^^^^^^^^^^^^^^^^^^^^^^^^^^^
  File "c:\Users\RUSTYCHKA\AppData\Local\Programs\Python\Python312\Lib\site-packages\requests\api.py", line 73, in get
    return request("get", url, params=params, **kwargs)
           ^^^^^^^^^^^^^^^^^^^^^^^^^^^^^^^^^^^^^^^^^^^^
  File "c:\Users\RUSTYCHKA\AppData\Local\Programs\Python\Python312\Lib\site-packages\requests\api.py", line 59, in request
    return session.request(method=method, url=url, **kwargs)
           ^^^^^^^^^^^^^^^^^^^^^^^^^^^^^^^^^^^^^^^^^^^^^^^^^
  File "c:\Users\RUSTYCHKA\AppData\Local\Programs\Python\Python312\Lib\site-packages\requests\sessions.py", line 575, in request
    prep = self.prepare_request(req)
           ^^^^^^^^^^^^^^^^^^^^^^^^^
  File "c:\Users\RUSTYCHKA\AppData\Local\Programs\Python\Python312\Lib\site-packages\requests\sessions.py", line 484, in prepare_request
    p.prepare(
  File "c:\Users\RUSTYCHKA\AppData\Local\Programs\Python\Python312\Lib\site-packages\requests\models.py", line 367, in prepare
    self.prepare_url(url, params)
  File "c:\Users\RUSTYCHKA\AppData\Local\Programs\Python\Python312\Lib\site-packages\requests\models.py", line 435, in prepare_url
    raise InvalidURL(*e.args)
requests.exceptions.InvalidURL: Failed to parse: ['media\\image.png']
