2025-02-03 19:47:07 - INFO - Start polling
2025-02-03 19:47:07 - INFO - Run polling for bot @odfopjdfiohniodfhopjdfh_bot id=7915533202 - 'ijdsgijsiodgjsiodgjiosg'
2025-02-03 19:58:20 - INFO - Update id=652330992 is handled. Duration 609 ms by bot id=7915533202
2025-02-03 19:58:41 - INFO - Update id=652330993 is handled. Duration 327 ms by bot id=7915533202
2025-02-03 19:58:44 - INFO - Update id=652330994 is handled. Duration 141 ms by bot id=7915533202
2025-02-03 19:58:49 - INFO - Update id=652330995 is handled. Duration 125 ms by bot id=7915533202
2025-02-03 19:59:09 - INFO - Update id=652330996 is handled. Duration 202 ms by bot id=7915533202
2025-02-03 19:59:10 - INFO - Update id=652330997 is handled. Duration 92 ms by bot id=7915533202
2025-02-03 19:59:13 - INFO - Update id=652330998 is handled. Duration 125 ms by bot id=7915533202
2025-02-03 19:59:54 - INFO - Connecting to 149.154.175.53:443/TcpFull...
2025-02-03 19:59:55 - INFO - Connection to 149.154.175.53:443/TcpFull complete!
2025-02-03 19:59:56 - INFO - Starting direct file download in chunks of 131072 at 0, stride 131072
2025-02-03 19:59:56 - INFO - File lives in another DC
2025-02-03 19:59:57 - INFO - Connecting to 149.154.167.41:443/TcpFull...
2025-02-03 19:59:59 - INFO - Connection to 149.154.167.41:443/TcpFull complete!
2025-02-03 19:59:59 - INFO - Exporting auth for new borrowed sender in DcOption(id=2, ip_address='149.154.167.41', port=443, ipv6=False, media_only=False, tcpo_only=False, cdn=False, static=False, this_port_only=False, secret=None)
2025-02-03 20:01:43 - INFO - Update id=652330999 is not handled. Duration 109328 ms by bot id=7915533202
2025-02-03 20:01:43 - ERROR - Cause exception while process update id=652330999 by bot id=7915533202
KeyError: 'candidates'
Traceback (most recent call last):
  File "c:\Users\RUSTYCHKA\AppData\Local\Programs\Python\Python312\Lib\site-packages\aiogram\dispatcher\dispatcher.py", line 309, in _process_update
    response = await self.feed_update(bot, update, **kwargs)
               ^^^^^^^^^^^^^^^^^^^^^^^^^^^^^^^^^^^^^^^^^^^^^
  File "c:\Users\RUSTYCHKA\AppData\Local\Programs\Python\Python312\Lib\site-packages\aiogram\dispatcher\dispatcher.py", line 158, in feed_update
    response = await self.update.wrap_outer_middleware(
               ^^^^^^^^^^^^^^^^^^^^^^^^^^^^^^^^^^^^^^^^
  File "c:\Users\RUSTYCHKA\AppData\Local\Programs\Python\Python312\Lib\site-packages\aiogram\dispatcher\middlewares\error.py", line 25, in __call__
    return await handler(event, data)
           ^^^^^^^^^^^^^^^^^^^^^^^^^^
  File "c:\Users\RUSTYCHKA\AppData\Local\Programs\Python\Python312\Lib\site-packages\aiogram\dispatcher\middlewares\user_context.py", line 27, in __call__
    return await handler(event, data)
           ^^^^^^^^^^^^^^^^^^^^^^^^^^
  File "c:\Users\RUSTYCHKA\AppData\Local\Programs\Python\Python312\Lib\site-packages\aiogram\fsm\middleware.py", line 41, in __call__
    return await handler(event, data)
           ^^^^^^^^^^^^^^^^^^^^^^^^^^
  File "c:\Users\RUSTYCHKA\AppData\Local\Programs\Python\Python312\Lib\site-packages\aiogram\dispatcher\event\telegram.py", line 121, in trigger
    return await wrapped_inner(event, kwargs)
           ^^^^^^^^^^^^^^^^^^^^^^^^^^^^^^^^^^
  File "c:\Users\RUSTYCHKA\AppData\Local\Programs\Python\Python312\Lib\site-packages\aiogram\dispatcher\event\handler.py", line 43, in call
    return await wrapped()
           ^^^^^^^^^^^^^^^
  File "c:\Users\RUSTYCHKA\AppData\Local\Programs\Python\Python312\Lib\site-packages\aiogram\dispatcher\dispatcher.py", line 276, in _listen_update
    return await self.propagate_event(update_type=update_type, event=event, **kwargs)
           ^^^^^^^^^^^^^^^^^^^^^^^^^^^^^^^^^^^^^^^^^^^^^^^^^^^^^^^^^^^^^^^^^^^^^^^^^^
  File "c:\Users\RUSTYCHKA\AppData\Local\Programs\Python\Python312\Lib\site-packages\aiogram\dispatcher\router.py", line 128, in propagate_event
    return await observer.wrap_outer_middleware(_wrapped, event=event, data=kwargs)
           ^^^^^^^^^^^^^^^^^^^^^^^^^^^^^^^^^^^^^^^^^^^^^^^^^^^^^^^^^^^^^^^^^^^^^^^^
  File "c:\Users\RUSTYCHKA\AppData\Local\Programs\Python\Python312\Lib\site-packages\aiogram\dispatcher\router.py", line 123, in _wrapped
    return await self._propagate_event(
           ^^^^^^^^^^^^^^^^^^^^^^^^^^^^
  File "c:\Users\RUSTYCHKA\AppData\Local\Programs\Python\Python312\Lib\site-packages\aiogram\dispatcher\router.py", line 156, in _propagate_event
    response = await router.propagate_event(update_type=update_type, event=event, **kwargs)
               ^^^^^^^^^^^^^^^^^^^^^^^^^^^^^^^^^^^^^^^^^^^^^^^^^^^^^^^^^^^^^^^^^^^^^^^^^^^^
  File "c:\Users\RUSTYCHKA\AppData\Local\Programs\Python\Python312\Lib\site-packages\aiogram\dispatcher\router.py", line 128, in propagate_event
    return await observer.wrap_outer_middleware(_wrapped, event=event, data=kwargs)
           ^^^^^^^^^^^^^^^^^^^^^^^^^^^^^^^^^^^^^^^^^^^^^^^^^^^^^^^^^^^^^^^^^^^^^^^^
  File "c:\Users\RUSTYCHKA\AppData\Local\Programs\Python\Python312\Lib\site-packages\aiogram\dispatcher\router.py", line 123, in _wrapped
    return await self._propagate_event(
           ^^^^^^^^^^^^^^^^^^^^^^^^^^^^
  File "c:\Users\RUSTYCHKA\AppData\Local\Programs\Python\Python312\Lib\site-packages\aiogram\dispatcher\router.py", line 148, in _propagate_event
    response = await observer.trigger(event, **kwargs)
               ^^^^^^^^^^^^^^^^^^^^^^^^^^^^^^^^^^^^^^^
  File "c:\Users\RUSTYCHKA\AppData\Local\Programs\Python\Python312\Lib\site-packages\aiogram\dispatcher\event\telegram.py", line 121, in trigger
    return await wrapped_inner(event, kwargs)
           ^^^^^^^^^^^^^^^^^^^^^^^^^^^^^^^^^^
  File "c:\Users\RUSTYCHKA\AppData\Local\Programs\Python\Python312\Lib\site-packages\aiogram\dispatcher\event\handler.py", line 43, in call
    return await wrapped()
           ^^^^^^^^^^^^^^^
  File "C:\Users\RUSTYCHKA\Desktop\new_vk_project\handlers\start.py", line 179, in start_callback
    ad_check_result = await call_gemini_api(GEMINI_API_KEY, ad_check_prompt)
                      ^^^^^^^^^^^^^^^^^^^^^^^^^^^^^^^^^^^^^^^^^^^^^^^^^^^^^^
  File "C:\Users\RUSTYCHKA\Desktop\new_vk_project\handlers\start.py", line 65, in call_gemini_api
    return f['candidates'][0]['content']['parts'][0]['text']
           ~^^^^^^^^^^^^^^
KeyError: 'candidates'
2025-02-03 20:01:43 - ERROR - Failed to fetch updates - TelegramNetworkError: HTTP Client says - Request timeout error
2025-02-03 20:01:43 - WARNING - Sleep for 1.000000 seconds and try again... (tryings = 0, bot id = 7915533202)
2025-02-03 20:01:43 - INFO - Disconnecting borrowed sender for DC 2
2025-02-03 20:01:43 - INFO - Disconnecting from 149.154.167.41:443/TcpFull...
2025-02-03 20:01:43 - INFO - Disconnection from 149.154.167.41:443/TcpFull complete!
2025-02-03 20:01:54 - ERROR - Failed to fetch updates - TelegramNetworkError: HTTP Client says - ClientOSError: [WinError 1236] Подключение к сети было разорвано локальной системой
2025-02-03 20:01:54 - WARNING - Sleep for 1.133254 seconds and try again... (tryings = 1, bot id = 7915533202)
2025-02-03 20:01:56 - WARNING - Server closed the connection: [WinError 1236] Подключение к сети было разорвано локальной системой
2025-02-03 20:01:56 - WARNING - Server closed the connection: [WinError 1236] Подключение к сети было разорвано локальной системой
2025-02-03 20:01:56 - INFO - Connection closed while receiving data
2025-02-03 20:01:56 - WARNING - Server closed the connection: [WinError 1236] Подключение к сети было разорвано локальной системой
2025-02-03 20:01:56 - INFO - Closing current connection to begin reconnect...
2025-02-03 20:01:56 - INFO - <class 'ConnectionAbortedError'> during disconnect: [WinError 1236] Подключение к сети было разорвано локальной системой
2025-02-03 20:01:56 - INFO - <class 'ConnectionAbortedError'> during disconnect: [WinError 1236] Подключение к сети было разорвано локальной системой
2025-02-03 20:01:56 - INFO - Connecting to 149.154.175.53:443/TcpFull...
2025-02-03 20:01:56 - WARNING - Attempt 1 at connecting failed: ConnectionError: [Errno 13] Could not connect to proxy 107.175.69.226:52117 [Отказано в доступе]
2025-02-03 20:01:56 - ERROR - Error on reading from the event loop self pipe
loop: <ProactorEventLoop running=True closed=False debug=False>
Traceback (most recent call last):
  File "c:\Users\RUSTYCHKA\AppData\Local\Programs\Python\Python312\Lib\asyncio\proactor_events.py", line 795, in _loop_self_reading
    f.result()  # may raise
    ^^^^^^^^^^
  File "c:\Users\RUSTYCHKA\AppData\Local\Programs\Python\Python312\Lib\asyncio\windows_events.py", line 803, in _poll
    value = callback(transferred, key, ov)
            ^^^^^^^^^^^^^^^^^^^^^^^^^^^^^^
  File "c:\Users\RUSTYCHKA\AppData\Local\Programs\Python\Python312\Lib\asyncio\windows_events.py", line 462, in finish_socket_func
    return ov.getresult()
           ^^^^^^^^^^^^^^
ConnectionAbortedError: [WinError 1236] Подключение к сети было разорвано локальной системой
